<?xml version="1.0" ?>
<!-- =================================================================================== -->
<!-- |    This document was autogenerated by xacro from /home/klb/Y_testfield/model_urdf_ws/src/ur5_grasping_demo/ur5_arm_description/urdf/ur5_robot_gripper.urdf.xacro | -->
<!-- |    EDITING THIS FILE BY HAND IS NOT RECOMMENDED                                 | -->
<!-- =================================================================================== -->
<robot name="ur5">
    <link name="world" />
    <gazebo>
        <plugin filename="libgazebo_ros_control.so" name="ros_control">
            <!--robotNamespace>/</robotNamespace-->
            <!--robotSimType>gazebo_ros_control/DefaultRobotHWSim</robotSimType-->
        </plugin>
        <!--
    <plugin name="gazebo_ros_power_monitor_controller" filename="libgazebo_ros_power_monitor.so">
      <alwaysOn>true</alwaysOn>
      <updateRate>1.0</updateRate>
      <timeout>5</timeout>
      <powerStateTopic>power_state</powerStateTopic>
      <powerStateRate>10.0</powerStateRate>
      <fullChargeCapacity>87.78</fullChargeCapacity>     
      <dischargeRate>-474</dischargeRate>
      <chargeRate>525</chargeRate>
      <dischargeVoltage>15.52</dischargeVoltage>
      <chargeVoltage>16.41</chargeVoltage>
    </plugin>
-->
        <plugin name="gazebo_ros_control">
            <robotNamespace>/</robotNamespace>
        </plugin>
    </gazebo>
    <!-- measured from model -->
    <!--property name="shoulder_height" value="0.089159" /-->
    <!--property name="shoulder_offset" value="0.13585" /-->
    <!-- shoulder_offset - elbow_offset + wrist_1_length = 0.10915 -->
    <!--property name="upper_arm_length" value="0.42500" /-->
    <!--property name="elbow_offset" value="0.1197" /-->
    <!-- CAD measured -->
    <!--property name="forearm_length" value="0.39225" /-->
    <!--property name="wrist_1_length" value="0.093" /-->
    <!-- CAD measured -->
    <!--property name="wrist_2_length" value="0.09465" /-->
    <!-- In CAD this distance is 0.930, but in the spec it is 0.09465 -->
    <!--property name="wrist_3_length" value="0.0823" /-->
    <!-- manually measured -->
    <link name="base_link">
        <visual>
            <geometry>
                <mesh filename="package://ur_description/meshes/ur5/visual/base.dae" />
            </geometry>
            <material name="LightGrey">
                <color rgba="0.7 0.7 0.7 1.0" />
            </material>
        </visual>
        <collision>
            <geometry>
                <mesh filename="package://ur_description/meshes/ur5/collision/base.stl" />
            </geometry>
        </collision>
        <inertial>
            <mass value="4.0" />
            <origin rpy="0 0 0" xyz="0.0 0.0 0.0" />
            <inertia ixx="0.00443333156" ixy="0.0" ixz="0.0" iyy="0.00443333156" iyz="0.0" izz="0.0072" />
        </inertial>
    </link>
    <joint name="shoulder_pan_joint" type="revolute">
        <parent link="base_link" />
        <child link="shoulder_link" />
        <origin rpy="0.0 0.0 0.0" xyz="0.0 0.0 0.089159" />
        <axis xyz="0 0 1" />
        <limit effort="150.0" lower="-6.283185307179586" upper="6.283185307179586" velocity="3.15" />
        <dynamics damping="0.0" friction="0.0" />
    </joint>
    <link name="shoulder_link">
        <visual>
            <geometry>
                <mesh filename="package://ur_description/meshes/ur5/visual/shoulder.dae" />
            </geometry>
            <material name="LightGrey">
                <color rgba="0.7 0.7 0.7 1.0" />
            </material>
        </visual>
        <collision>
            <geometry>
                <mesh filename="package://ur_description/meshes/ur5/collision/shoulder.stl" />
            </geometry>
        </collision>
        <inertial>
            <mass value="3.7" />
            <origin rpy="0 0 0" xyz="0.0 0.0 0.0" />
            <inertia ixx="0.010267495893" ixy="0.0" ixz="0.0" iyy="0.010267495893" iyz="0.0" izz="0.00666" />
        </inertial>
    </link>
    <joint name="shoulder_lift_joint" type="revolute">
        <parent link="shoulder_link" />
        <child link="upper_arm_link" />
        <origin rpy="0.0 1.5707963267948966 0.0" xyz="0.0 0.13585 0.0" />
        <axis xyz="0 1 0" />
        <limit effort="150.0" lower="-6.283185307179586" upper="6.283185307179586" velocity="3.15" />
        <dynamics damping="0.0" friction="0.0" />
    </joint>
    <link name="upper_arm_link">
        <visual>
            <geometry>
                <mesh filename="package://ur_description/meshes/ur5/visual/upperarm.dae" />
            </geometry>
            <material name="LightGrey">
                <color rgba="0.7 0.7 0.7 1.0" />
            </material>
        </visual>
        <collision>
            <geometry>
                <mesh filename="package://ur_description/meshes/ur5/collision/upperarm.stl" />
            </geometry>
        </collision>
        <inertial>
            <mass value="8.393" />
            <origin rpy="0 0 0" xyz="0.0 0.0 0.28" />
            <inertia ixx="0.22689067591036005" ixy="0.0" ixz="0.0" iyy="0.22689067591036005" iyz="0.0" izz="0.0151074" />
        </inertial>
    </link>
    <joint name="elbow_joint" type="revolute">
        <parent link="upper_arm_link" />
        <child link="forearm_link" />
        <origin rpy="0.0 0.0 0.0" xyz="0.0 -0.1197 0.425" />
        <axis xyz="0 1 0" />
        <limit effort="150.0" lower="-3.141592653589793" upper="3.141592653589793" velocity="3.15" />
        <dynamics damping="0.0" friction="0.0" />
    </joint>
    <link name="forearm_link">
        <visual>
            <geometry>
                <mesh filename="package://ur_description/meshes/ur5/visual/forearm.dae" />
            </geometry>
            <material name="LightGrey">
                <color rgba="0.7 0.7 0.7 1.0" />
            </material>
        </visual>
        <collision>
            <geometry>
                <mesh filename="package://ur_description/meshes/ur5/collision/forearm.stl" />
            </geometry>
        </collision>
        <inertial>
            <mass value="2.275" />
            <origin rpy="0 0 0" xyz="0.0 0.0 0.196125" />
            <inertia ixx="0.03121679102890359" ixy="0.0" ixz="0.0" iyy="0.03121679102890359" iyz="0.0" izz="0.004095" />
        </inertial>
    </link>
    <joint name="wrist_1_joint" type="revolute">
        <parent link="forearm_link" />
        <child link="wrist_1_link" />
        <origin rpy="0.0 1.5707963267948966 0.0" xyz="0.0 0.0 0.39225" />
        <axis xyz="0 1 0" />
        <limit effort="28.0" lower="-6.283185307179586" upper="6.283185307179586" velocity="3.2" />
        <dynamics damping="0.0" friction="0.0" />
    </joint>
    <link name="wrist_1_link">
        <visual>
            <geometry>
                <mesh filename="package://ur_description/meshes/ur5/visual/wrist1.dae" />
            </geometry>
            <material name="LightGrey">
                <color rgba="0.7 0.7 0.7 1.0" />
            </material>
        </visual>
        <collision>
            <geometry>
                <mesh filename="package://ur_description/meshes/ur5/collision/wrist1.stl" />
            </geometry>
        </collision>
        <inertial>
            <mass value="1.219" />
            <origin rpy="0 0 0" xyz="0.0 0.093 0.0" />
            <inertia ixx="0.0025598989760400002" ixy="0.0" ixz="0.0" iyy="0.0025598989760400002" iyz="0.0" izz="0.0021942" />
        </inertial>
    </link>
    <joint name="wrist_2_joint" type="revolute">
        <parent link="wrist_1_link" />
        <child link="wrist_2_link" />
        <origin rpy="0.0 0.0 0.0" xyz="0.0 0.093 0.0" />
        <axis xyz="0 0 1" />
        <limit effort="28.0" lower="-6.283185307179586" upper="6.283185307179586" velocity="3.2" />
        <dynamics damping="0.0" friction="0.0" />
    </joint>
    <link name="wrist_2_link">
        <visual>
            <geometry>
                <mesh filename="package://ur_description/meshes/ur5/visual/wrist2.dae" />
            </geometry>
            <material name="LightGrey">
                <color rgba="0.7 0.7 0.7 1.0" />
            </material>
        </visual>
        <collision>
            <geometry>
                <mesh filename="package://ur_description/meshes/ur5/collision/wrist2.stl" />
            </geometry>
        </collision>
        <inertial>
            <mass value="1.219" />
            <origin rpy="0 0 0" xyz="0.0 0.0 0.09465" />
            <inertia ixx="0.0025598989760400002" ixy="0.0" ixz="0.0" iyy="0.0025598989760400002" iyz="0.0" izz="0.0021942" />
        </inertial>
    </link>
    <joint name="wrist_3_joint" type="revolute">
        <parent link="wrist_2_link" />
        <child link="wrist_3_link" />
        <origin rpy="0.0 0.0 0.0" xyz="0.0 0.0 0.09465" />
        <axis xyz="0 1 0" />
        <limit effort="28.0" lower="-6.283185307179586" upper="6.283185307179586" velocity="3.2" />
        <dynamics damping="0.0" friction="0.0" />
    </joint>
    <link name="wrist_3_link">
        <visual>
            <geometry>
                <mesh filename="package://ur_description/meshes/ur5/visual/wrist3.dae" />
            </geometry>
            <material name="LightGrey">
                <color rgba="0.7 0.7 0.7 1.0" />
            </material>
        </visual>
        <collision>
            <geometry>
                <mesh filename="package://ur_description/meshes/ur5/collision/wrist3.stl" />
            </geometry>
        </collision>
        <inertial>
            <mass value="0.1879" />
            <origin rpy="1.5707963267948966 0 0" xyz="0.0 0.06505 0.0" />
            <inertia ixx="8.469589112163e-05" ixy="0.0" ixz="0.0" iyy="8.469589112163e-05" iyz="0.0" izz="0.0001321171875" />
        </inertial>
    </link>
    <joint name="ee_fixed_joint" type="fixed">
        <parent link="wrist_3_link" />
        <child link="ee_link" />
        <origin rpy="0.0 0.0 1.5707963267948966" xyz="0.0 0.0823 0.0" />
    </joint>
    <link name="ee_link">
        <collision>
            <geometry>
                <box size="0.01 0.01 0.01" />
            </geometry>
            <origin rpy="0 0 0" xyz="-0.01 0 0" />
        </collision>
        <inertial>
            <mass value="0.1" />
            <origin xyz="0 0 0" rpy="0 0 0" />
            <inertia ixx="0.03" iyy="0.03" izz="0.03" ixy="0.0" ixz="0.0" iyz="0.0" />
        </inertial>
    </link>
    <transmission name="shoulder_pan_trans">
        <type>transmission_interface/SimpleTransmission</type>
        <joint name="shoulder_pan_joint">
            <hardwareInterface>hardware_interface/PositionJointInterface</hardwareInterface>
        </joint>
        <actuator name="shoulder_pan_motor">
            <mechanicalReduction>1</mechanicalReduction>
            <hardwareInterface>hardware_interface/EffortJointInterface</hardwareInterface>
        </actuator>
    </transmission>
    <transmission name="shoulder_lift_trans">
        <type>transmission_interface/SimpleTransmission</type>
        <joint name="shoulder_lift_joint">
            <hardwareInterface>hardware_interface/PositionJointInterface</hardwareInterface>
        </joint>
        <actuator name="shoulder_lift_motor">
            <mechanicalReduction>1</mechanicalReduction>
            <hardwareInterface>hardware_interface/EffortJointInterface</hardwareInterface>
        </actuator>
    </transmission>
    <transmission name="elbow_trans">
        <type>transmission_interface/SimpleTransmission</type>
        <joint name="elbow_joint">
            <hardwareInterface>hardware_interface/PositionJointInterface</hardwareInterface>
        </joint>
        <actuator name="elbow_motor">
            <mechanicalReduction>1</mechanicalReduction>
            <hardwareInterface>hardware_interface/EffortJointInterface</hardwareInterface>
        </actuator>
    </transmission>
    <transmission name="wrist_1_trans">
        <type>transmission_interface/SimpleTransmission</type>
        <joint name="wrist_1_joint">
            <hardwareInterface>hardware_interface/PositionJointInterface</hardwareInterface>
        </joint>
        <actuator name="wrist_1_motor">
            <mechanicalReduction>1</mechanicalReduction>
            <hardwareInterface>hardware_interface/EffortJointInterface</hardwareInterface>
        </actuator>
    </transmission>
    <transmission name="wrist_2_trans">
        <type>transmission_interface/SimpleTransmission</type>
        <joint name="wrist_2_joint">
            <hardwareInterface>hardware_interface/PositionJointInterface</hardwareInterface>
        </joint>
        <actuator name="wrist_2_motor">
            <mechanicalReduction>1</mechanicalReduction>
            <hardwareInterface>hardware_interface/EffortJointInterface</hardwareInterface>
        </actuator>
    </transmission>
    <transmission name="wrist_3_trans">
        <type>transmission_interface/SimpleTransmission</type>
        <joint name="wrist_3_joint">
            <hardwareInterface>hardware_interface/PositionJointInterface</hardwareInterface>
        </joint>
        <actuator name="wrist_3_motor">
            <mechanicalReduction>1</mechanicalReduction>
            <hardwareInterface>hardware_interface/EffortJointInterface</hardwareInterface>
        </actuator>
    </transmission>
    <gazebo reference="shoulder_link">
        <selfCollide>true</selfCollide>
    </gazebo>
    <gazebo reference="upper_arm_link">
        <selfCollide>true</selfCollide>
    </gazebo>
    <gazebo reference="forearm_link">
        <selfCollide>true</selfCollide>
    </gazebo>
    <gazebo reference="wrist_1_link">
        <selfCollide>true</selfCollide>
    </gazebo>
    <gazebo reference="wrist_3_link">
        <selfCollide>true</selfCollide>
    </gazebo>
    <gazebo reference="wrist_2_link">
        <selfCollide>true</selfCollide>
    </gazebo>
    <gazebo reference="ee_link">
        <selfCollide>true</selfCollide>
    </gazebo>
    <!-- ROS base_link to UR 'Base' Coordinates transform -->
    <link name="base" />
    <joint name="base_link-base_fixed_joint" type="fixed">
        <!-- NOTE: this rotation is only needed as long as base_link itself is
                 not corrected wrt the real robot (ie: rotated over 180
                 degrees)
      -->
        <origin rpy="0 0 -3.141592653589793" xyz="0 0 0" />
        <parent link="base_link" />
        <child link="base" />
    </joint>
    <!-- Frame coincident with all-zeros TCP on UR controller -->
    <link name="tool0" />
    <joint name="wrist_3_link-tool0_fixed_joint" type="fixed">
        <origin rpy="-1.5707963267948966 0 0" xyz="0 0.14229999999999998 0" />
        <parent link="wrist_3_link" />
        <child link="tool0" />
    </joint>
    <joint name="pg70_palm_joint" type="fixed">
        <parent link="ee_link" />
        <child link="pg70_palm_link" />
        <origin rpy="0 1.57 0" xyz="0 0 0" />
    </joint>
    <link name="pg70_palm_link">
        <inertial>
            <origin rpy="0 0 0" xyz="0 0 0" />
            <mass value="1" />
            <inertia ixx="0.01" ixy="0" ixz="0" iyy="0.01" iyz="0" izz="0.01" />
        </inertial>
        <visual>
            <geometry>
                <mesh filename="package://schunk_description/meshes/pg70/pg70.dae" />
            </geometry>
            <material name="blue">
                <color rgba="0 0 1 1" />
            </material>
        </visual>
        <collision>
            <geometry>
                <mesh filename="package://schunk_description/meshes/pg70/pg70.dae" />
            </geometry>
            <material name="blue">
                <color rgba="0 0 1 1" />
            </material>
        </collision>
    </link>
    <joint name="pg70_finger_left_joint" type="prismatic">
        <parent link="pg70_palm_link" />
        <child link="pg70_finger_left_link" />
        <limit effort="100" lower="-0.001" upper="0.061" velocity="2.0" />
        <origin rpy="0 0 0" xyz="0 0 0.0789" />
        <axis xyz="0 1 0" />
    </joint>
    <link name="pg70_finger_left_link">
        <inertial>
            <origin rpy="0 0 0" xyz="0 0 0" />
            <mass value="1" />
            <inertia ixx="0.01" ixy="0" ixz="0" iyy="0.01" iyz="0" izz="0.01" />
        </inertial>
        <visual>
            <geometry>
                <box size="0.03 0.01 0.01" />
            </geometry>
            <material name="black">
                <color rgba="0 0 0 1" />
            </material>
        </visual>
        <collision>
            <geometry>
                <box size="0.03 0.01 0.01" />
            </geometry>
            <material name="black">
                <color rgba="0 0 0 1" />
            </material>
        </collision>
    </link>
    <joint name="pg70_finger_right_joint" type="prismatic">
        <mimic joint="pg70_finger_left_joint" multiplier="1" offset="0" />
        <parent link="pg70_palm_link" />
        <child link="pg70_finger_right_link" />
        <limit effort="100" lower="-0.001" upper="0.061" velocity="2.0" />
        <origin rpy="-0 0 0" xyz="0 0 0.0789" />
        <axis xyz="0 -1 0" />
    </joint>
    <link name="pg70_finger_right_link">
        <inertial>
            <origin rpy="0 0 0" xyz="0 0 0" />
            <mass value="1" />
            <inertia ixx="0.01" ixy="0" ixz="0" iyy="0.01" iyz="0" izz="0.01" />
        </inertial>
        <visual>
            <geometry>
                <box size="0.03 0.01 0.01" />
            </geometry>
            <material name="black">
                <color rgba="0 0 0 1" />
            </material>
        </visual>
        <collision>
            <geometry>
                <box size="0.03 0.01 0.01" />
            </geometry>
            <material name="black">
                <color rgba="0 0 0 1" />
            </material>
        </collision>
    </link>
    <gazebo reference="pg70_palm_link">
        <gravity>true</gravity>
        <self_collide>false</self_collide>
        <material>Schunk/LightGrey</material>
    </gazebo>
    <gazebo reference="pg70_finger_left_link">
        <gravity>true</gravity>
        <self_collide>false</self_collide>
        <material>Schunk/LightGrey</material>
    </gazebo>
    <gazebo reference="pg70_finger_right_link">
        <gravity>true</gravity>
        <self_collide>false</self_collide>
        <material>Schunk/LightGrey</material>
    </gazebo>
    <!-- finger1 -->
    <transmission name="pg70_finger_left_trans">
        <type>transmission_interface/SimpleTransmission</type>
        <joint name="pg70_finger_left_joint">
            <hardwareInterface>EffortJointInterface</hardwareInterface>
            <hardwareInterface>PositionJointInterface</hardwareInterface>
            <hardwareInterface>VelocityJointInterface</hardwareInterface>
        </joint>
        <actuator name="pg70_finger_left_motor">
            <mechanicalReduction>0.5</mechanicalReduction>
            <hardwareInterface>hardware_interface/EffortJointInterface</hardwareInterface>
        </actuator>
    </transmission>
    <!-- finger2 - mimic -->
    <transmission name="pg70_finger_right_trans">
        <type>transmission_interface/SimpleTransmission</type>
        <joint name="pg70_finger_right_joint">
            <hardwareInterface>EffortJointInterface</hardwareInterface>
            <hardwareInterface>PositionJointInterface</hardwareInterface>
            <hardwareInterface>VelocityJointInterface</hardwareInterface>
        </joint>
        <actuator name="pg70_finger_right_motor">
            <mechanicalReduction>0.5</mechanicalReduction>
            <hardwareInterface>hardware_interface/EffortJointInterface</hardwareInterface>
        </actuator>
    </transmission>
    <!-- robotiq 85 -->
    <!-- <xacro:include filename="$(find robotiq_85_description)/urdf/robotiq_85_gripper.urdf.xacro" /> -->
    <!-- gripper，加载夹爪，并链接到ur5的ee_link -->
    <!-- <xacro:robotiq_85_gripper prefix="" parent="ee_link" > -->
    <!-- <origin xyz="0 0 0" rpy="0 0 0"/> -->
    <!-- </xacro:robotiq_85_gripper> -->
    <!-- 该部分为选配各类夹爪 -->
    <gazebo reference="kinect2_base_link">
        <material>Gazebo/Grey</material>
    </gazebo>
    <joint name="kinect2_joint" type="fixed">
        <insert_block name="origin" />
        <parent link="world" />
        <!-- <parent link="world" /> -->
        <child link="kinect2_base_link" />
        <origin rpy="0 1.57 0" xyz="0.4 0 2.0" />
    </joint>
    <link name="kinect2_base_link">
        <inertial>
            <origin rpy="0 0 0" xyz="-0.0028247 0.00047839 0.038307" />
            <mass value="0.82085" />
            <inertia ixx="0.0039702" ixy="0" ixz="0" iyy="0.00059235" iyz="0" izz="0.0041195" />
        </inertial>
        <visual>
            <origin rpy="0 0 0" xyz="0 0 0" />
            <geometry>
                <mesh filename="package://kinect_v2/meshes/kinect2.STL" />
            </geometry>
            <material name="">
                <color rgba="0.5 0.5 0.5 1" />
            </material>
        </visual>
        <collision>
            <origin rpy="0 0 0" xyz="0 0 0" />
            <geometry>
                <mesh filename="package://kinect_v2/meshes/kinect2.STL" />
            </geometry>
        </collision>
    </link>
    <!-- kinect2 rgb sensor physical attachment -->
    <joint name="kinect2_rgb_joint" type="fixed">
        <origin rpy="0 0 0" xyz="0.032 -0.095 0.042015" />
        <parent link="kinect2_base_link" />
        <child link="kinect2_rgb_link" />
    </joint>
    <link name="kinect2_rgb_link" />
    <!-- kinect2 rgb sensor frame -->
    <joint name="kinect2_rgb_optical_frame_joint" type="fixed">
        <origin rpy="-1.570795 0 -1.570795" xyz="0 0 0" />
        <parent link="kinect2_rgb_link" />
        <child link="kinect2_rgb_optical_frame" />
    </joint>
    <link name="kinect2_rgb_optical_frame" />
    <gazebo reference="kinect2_rgb_link">
        <sensor name="kinect_v2_rgb_sensor" type="depth">
            <always_on>true</always_on>
            <update_rate>1.0</update_rate>
            <camera>
                <horizontal_fov>0.9948368333333333</horizontal_fov>
                <image>
                    <format>B8G8R8</format>
                    <width>640</width>
                    <height>480</height>
                </image>
                <clip>
                    <near>0.01</near>
                    <far>5</far>
                </clip>
            </camera>
            <plugin filename="libgazebo_ros_openni_kinect.so" name="kinect2_rgb_link_controller">
                <alwaysOn>true</alwaysOn>
                <updateRate>1.0</updateRate>
                <cameraName>kinect_V2_rgb</cameraName>
                <imageTopicName>/kinect_V2/rgb/image_raw</imageTopicName>
                <cameraInfoTopicName>/kinect_V2/rgb/camera_info</cameraInfoTopicName>
                <depthImageTopicName>/kinect_V2/depth/image_raw</depthImageTopicName>
                <depthImageCameraInfoTopicName>/kinect_V2/depth/camera_info</depthImageCameraInfoTopicName>
                <pointCloudTopicName>/kinect_V2/depth_registered/points</pointCloudTopicName>
                <frameName>kinect2_rgb_optical_frame</frameName>
                <pointCloudCutoff>0.5</pointCloudCutoff>
                <distortionK1>0.00000001</distortionK1>
                <distortionK2>0.00000001</distortionK2>
                <distortionK3>0.00000001</distortionK3>
                <distortionT1>0.00000001</distortionT1>
                <distortionT2>0.00000001</distortionT2>
                <CxPrime>0</CxPrime>
                <Cx>0</Cx>
                <Cy>0</Cy>
                <focalLength>0</focalLength>
                <hackBaseline>0</hackBaseline>
            </plugin>
        </sensor>
        <material value="Gazebo/Red" />
    </gazebo>
    <!-- kinect2 ir sensor physical attachment -->
    <joint name="kinect2_ir_joint" type="fixed">
        <origin rpy="0 0 0" xyz="0 0.05157 0" />
        <parent link="kinect2_rgb_link" />
        <child link="kinect2_ir_link" />
    </joint>
    <link name="kinect2_ir_link" />
    <!-- kinect2 ir sensor frame -->
    <joint name="kinect2_ir_optical_frame_joint" type="fixed">
        <origin rpy="-1.570795 0 -1.570795" xyz="0 0 0" />
        <parent link="kinect2_ir_link" />
        <child link="kinect2_ir_optical_frame" />
    </joint>
    <link name="kinect2_ir_optical_frame" />
    <gazebo reference="kinect2_ir_link">
        <sensor name="kinectv2_ir_sensor" type="depth">
            <always_on>true</always_on>
            <update_rate>1.0</update_rate>
            <camera>
                <horizontal_fov>0.9948368333333333</horizontal_fov>
                <image>
                    <format>L8</format>
                    <width>640</width>
                    <height>480</height>
                </image>
                <clip>
                    <near>0.01</near>
                    <far>5</far>
                </clip>
            </camera>
            <plugin filename="libgazebo_ros_openni_kinect.so" name="kinect2_ir_link_controller">
                <baseline>0.2</baseline>
                <alwaysOn>true</alwaysOn>
                <updateRate>1.0</updateRate>
                <cameraName>kinect_V2_ir</cameraName>
                <imageTopicName>/kinect_V2/ir/image_raw</imageTopicName>
                <cameraInfoTopicName>/kinect_V2/ir/camera_info</cameraInfoTopicName>
                <depthImageTopicName>/kinect_V2/depth/image_raw</depthImageTopicName>
                <depthImageCameraInfoTopicName>/kinect_V2/depth/camera_info</depthImageCameraInfoTopicName>
                <pointCloudTopicName>/kinect_V2/depth/points</pointCloudTopicName>
                <frameName>kinect2_ir_optical_frame</frameName>
                <pointCloudCutoff>0.5</pointCloudCutoff>
                <distortionK1>0.00000001</distortionK1>
                <distortionK2>0.00000001</distortionK2>
                <distortionK3>0.00000001</distortionK3>
                <distortionT1>0.00000001</distortionT1>
                <distortionT2>0.00000001</distortionT2>
                <CxPrime>0</CxPrime>
                <Cx>0</Cx>
                <Cy>0</Cy>
                <focalLength>0</focalLength>
                <hackBaseline>0</hackBaseline>
            </plugin>
        </sensor>
        <material value="Gazebo/Red" />
    </gazebo>
    <link name="robot_pilar">
        <visual>
            <geometry>
                <cylinder length="0.9" radius="0.07" />
            </geometry>
            <material name="blue">
                <color rgba="0 0 .8 1" />
            </material>
        </visual>
        <collision>
            <geometry>
                <cylinder length="0.9" radius="0.07" />
            </geometry>
        </collision>
        <inertial>
            <mass value="1" />
            <inertia ixx="0.145833" ixy="0.0" ixz="0.0" iyy="0.145833" iyz="0.0" izz="0.125" />
            <origin xyz="0 0 0" rpy="0 0 0" />
        </inertial>
    </link>
    <!-- 对ur5与 自定义柱子 进行链接 -->
    <!-- 柱子与世界 -->
    <joint name="pilar_to_world" type="fixed">
        <parent link="world" />
        <child link="robot_pilar" />
        <origin rpy="0 0 0" xyz="0 0 0.45" />
    </joint>
    <!-- ur5与柱子 -->
    <joint name="robot_to_pilar" type="fixed">
        <parent link="robot_pilar" />
        <child link="base_link" />
        <origin rpy="0 0 0" xyz="0 0 0.45" />
    </joint>
</robot>

